Workbook

Sheet Raw_Data
A1: Sr.NO | B1: shortName | C1: industry | D1: ebitdaMargins | E1: profitMargins | F1: grossMargins | G1: operatingCashflow | H1: revenueGrowth | I1: operatingMargins | J1: ebitda | K1: grossProfits | L1: freeCashflow | M1: currentPrice | N1: earningsGrowth | O1: currentRatio | P1: returnOnAssets | Q1: debtToEquity | R1: returnOnEquity | S1: totalCash | T1: totalDebt | U1: totalRevenue | V1: totalCashPerShare | W1: financialCurrency | X1: revenuePerShare | Y1: quickRatio | Z1: quoteType | AA1: symbol | AB1: enterpriseToRevenue | AC1: enterpriseToEbitda | AD1: forwardEps | AE1: sharesOutstanding | AF1: bookValue | AG1: trailingEps | AH1: priceToBook | AI1: heldPercentInsiders | AJ1: enterpriseValue | AK1: earningsQuarterlyGrowth | AL1: pegRatio | AM1: forwardPE | AN1: marketCap
A2: 0 | B2: Apple Inc. | C2: Consumer Electronics | D2: 0.33890998 | E2: 0.26579002 | F2: 0.43019 | G2: 112241000448 | H2: 0.112 | I2: 0.309 | J2: 128217997312 | K2: 152836000000 | L2: 80153247744 | M2: 174.72 | N2: 0.25 | O2: 1.038 | P2: 0.19875 | Q2: 170.714 | R2: 1.45567 | S2: 63913000960 | T2: 122797998080 | U2: 378323009536 | V2: 3.916 | W2: USD | X2: 22.838 | Y2: 0.875 | Z2: EQUITY | AA2: AAPL | AB2: 7.692 | AC2: 22.697 | AD2: 6.56 | AE2: 16319399936 | AF2: 4.402 | AG2: 6.015 | AH2: 39.69105 | AI2: 0.0007 | AJ2: 2910217830400 | AK2: 0.204 | AL2: 1.9 | AM2: 26.634148 | AN2: 2851325607936
A3: 1 | B3: Microsoft Corporation | C3: Software—Infrastructure | D3: 0.49123 | E3: 0.38498002 | F3: 0.68825996 | G3: 83909001216 | H3: 0.201 | I3: 0.42523998 | J3: 90829996032 | K3: 115856000000 | L3: 46479876096 | M3: 303.68 | N3: 0.222 | O3: 2.247 | P3: 0.15248999 | Q3: 50.217 | R3: 0.49051 | S3: 125348003840 | T3: 80353001472 | U3: 184902991872 | V3: 16.72 | W3: USD | X3: 24.585 | Y3: 2.05 | Z3: EQUITY | AA3: MSFT | AB3: 12.069 | AC3: 24.57 | AD3: 10.75 | AE3: 7496869888 | AF3: 21.335 | AG3: 9.389 | AH3: 14.233889 | AI3: 0.00059 | AJ3: 2231653367808 | AK3: 0.214 | AL3: 1.87 | AM3: 28.249302 | AN3: 2276649336832
A4: 2 | B4: Alphabet Inc. | C4: Internet Content & Information | D4: 0.35377 | E4: 0.29512 | F4: 0.5694 | G4: 91651997696 | H4: 0.324 | I4: 0.30552 | J4: 91144003584 | K4: 146698000000 | L4: 49490001920 | M4: 2830.43 | N4: 0.377 | O4: 2.928 | P4: 0.14493 | Q4: 11.329 | R4: 0.32069 | S4: 139649007616 | T4: 28508000256 | U4: 257637007360 | V4: 211.278 | W4: USD | X4: 385.886 | Y4: 2.8 | Z4: EQUITY | AA4: GOOG | AB4: 6.83 | AC4: 19.307 | AD4: 136.06 | AE4: 315639008 | AF4: 380.044 | AG4: 112.197 | AH4: 7.4476376 | AI4: 0.00034000003 | AJ4: 1759692062720 | AK4: 0.356 | AL4: 1.22 | AM4: 20.802807 | AN4: 1872632217600
A5: 3 | B5: Alphabet Inc. | C5: Internet Content & Information | D5: 0.35377 | E5: 0.29512 | F5: 0.5694 | G5: 91651997696 | H5: 0.324 | I5: 0.30552 | J5: 91144003584 | K5: 146698000000 | L5: 49490001920 | M5: 2833.46 | N5: 0.377 | O5: 2.928 | P5: 0.14493 | Q5: 11.329 | R5: 0.32069 | S5: 139649007616 | T5: 28508000256 | U5: 257637007360 | V5: 211.278 | W5: USD | X5: 385.886 | Y5: 2.8 | Z5: EQUITY | AA5: GOOGL | AB5: 6.838 | AC5: 19.329 | AD5: 135.95 | AE5: 300755008 | AF5: 380.044 | AG5: 112.197 | AH5: 7.4556103 | AI5: 0.077020004 | AJ5: 1761694842880 | AK5: 0.356 | AL5: 1.22 | AM5: 20.841927 | AN5: 1871194226688
A6: 4 | B6: Amazon.com, Inc. | C6: Internet Retail | D6: 0.12595001 | E6: 0.07101 | F6: 0.42032 | G6: 46327001088 | H6: 0.094 | I6: 0.052950002 | J6: 59174998016 | K6: 197478000000 | L6: -787249984 | M6: 3295.47 | N6: 0.975 | O6: 1.136 | P6: 0.041929998 | Q6: 100.864 | R6: 0.28806 | S6: 96048996352 | T6: 139438997504 | U6: 469822013440 | V6: 188.759 | W6: USD | X6: 928.502 | Y6: 0.905 | Z6: EQUITY | AA6: AMZN | AB6: 3.662 | AC6: 29.071 | AD6: 72.85 | AE6: 508844000 | AF6: 271.601 | AG6: 64.81 | AH6: 12.133496 | AI6: 0.09884 | AJ6: 1720271503360 | AK6: 0.983 | AL6: 1.93 | AM6: 45.236378 | AN6: 1676880117760
A7: 5 | B7: Tesla, Inc. | C7: Auto Manufacturers | D7: 0.15512 | E7: 0.07403 | F7: 0.23107 | G7: 9930999808 | H7: 0.568 | I7: 0.09789 | J7: 7266999808 | K7: 6630000000 | L7: 4644624896 | M7: 1010.64 | N7: 4.333 | O7: 1.385 | P7: 0.055370003 | Q7: 35.65 | R7: 0.15641 | S7: 16094999552 | T7: 10158000128 | U7: 46848000000 | V7: 16.027 | W7: USD | X7: 48.272 | Y7: 1.002 | Z7: EQUITY | AA7: TSLA | AB7: 24.547 | AC7: 158.249 | AD7: 8.76 | AE7: 1004259968 | AF7: 26.945 | AG7: 3.062 | AH7: 37.507515 | AI7: 0.19959 | AJ7: 1149996892160 | AK7: 3.888 | AL7: 2.52 | AM7: 115.36987 | AN7: 1014945284096
A8: 7 | B8: NVIDIA Corporation | C8: Semiconductors | D8: 0.40203 | E8: 0.33806 | F8: 0.64398 | G8: 8142000128 | H8: 0.503 | I8: 0.35454 | J8: 9758999552 | K8: 10557000000 | L8: 5935249920 | M8: 276.92 | N8: 0.83 | O8: 7.145 | P8: 0.15934 | Q8: 49.697 | R8: 0.41939998 | S8: 19298000896 | T8: 11827000320 | U8: 24273999872 | V8: 7.719 | W8: USD | X8: 9.75 | Y8: 6.437 | Z8: EQUITY | AA8: NVDA | AB8: 29.858 | AC8: 74.268 | AD8: 5.21 | AE8: 2492000000 | AF8: 9.512 | AG8: 3.243 | AH8: 29.112701 | AI8: 0.04079 | AJ8: 724779008000 | AK8: 0.844 | AL8: 1.71 | AM8: 53.151634 | AN8: 690084642816
A9: 8 | B9: Meta Platforms, Inc. | C9: Internet Content & Information | D9: 0.46401 | E9: 0.33383998 | F9: 0.80794 | G9: 57683001344 | H9: 0.199 | I9: 0.39645 | J9: 54720000000 | K9: 95280000000 | L9: 28807624704 | M9: 221.82 | N9: -0.052 | O9: 3.154 | P9: 0.17965001 | Q9: 11.574 | R9: 0.31102 | S9: 47998001152 | T9: 14453999616 | U9: 117929000960 | V9: 17.634 | W9: USD | X9: 41.893 | Y9: 2.935 | Z9: EQUITY | AA9: FB | AB9: 4.586 | AC9: 9.884 | AD9: 14.23 | AE9: 2366279936 | AF9: 47.748 | AG9: 13.974 | AH9: 4.6456394 | AI9: 0.0053100004 | AJ9: 540867395584 | AK9: -0.083 | AL9: 1.13 | AM9: 15.588195 | AN9: 617050013696
A10: 9 | B10: UnitedHealth Group Incorporated | C10: Healthcare Plans | D10: 0.086619996 | E10: 0.05523 | F10: 0.24284 | G10: 25226000384 | H10: 0.111 | I10: 0.07857 | J10: 24195999744 | K10: 67000000000 | L10: 24690499584 | M10: 513.03 | N10: 0.297 | O10: 0.72 | P10: 0.0679 | Q10: 62.929 | R10: 0.21985 | S10: 23871000576 | T10: 46964998144 | U10: 279320985600 | V10: 25.345 | W10: USD | X10: 295.5 | Y10: 0.655 | Z10: EQUITY | AA10: UNH | AB10: 1.754 | AC10: 20.243 | AD10: 21.65 | AE10: 941851008 | AF10: 74.605 | AG10: 16.111 | AH10: 6.876617 | AI10: 0.00548 | AJ10: 489802792960 | AK10: 0.288 | AL10: 1.84 | AM10: 23.696537 | AN10: 483197845504
A11: 10 | B11: Visa Inc. | C11: Credit Services | D11: 0.69612 | E11: 0.51592 | F11: 0.97068 | G11: 15946000384 | H11: 0.241 | I11: 0.66452 | J11: 17735000064 | K11: 23375000000 | L11: 12081874944 | M11: 218.43 | N11: 0.291 | O11: 1.395 | P11: 0.13035 | Q11: 57.8 | R11: 0.35584998 | S11: 15921000448 | T11: 20920000512 | U11: 25476999168 | V11: 7.591 | W11: USD | X11: 12.01 | Y11: 1.07 | Z11: EQUITY | AA11: V | AB11: 18.203 | AC11: 26.149 | AI11: 0.0013600001 | AJ11: 463753445376 | AK11: 0.266
A12: 11 | B12: Johnson & Johnson | C12: Drug Manufacturers—General | D12: 0.34803 | E12: 0.22264 | F12: 0.6827 | G12: 23409999872 | H12: 0.104 | I12: 0.26923 | J12: 32636999680 | K12: 64020000000 | L12: 18816999424 | M12: 176.92 | N12: 1.723 | O12: 1.348 | P12: 0.08842 | Q12: 46.946 | R12: 0.30412 | S12: 31608000512 | T12: 34751000576 | U12: 93775003648 | V12: 12.022 | W12: USD | X12: 35.627 | Y12: 1.037 | Z12: EQUITY | AA12: JNJ | AB12: 4.467 | AC12: 12.836 | AD12: 10.38 | AE12: 2632600064 | AF12: 26.694 | AG12: 6.691 | AH12: 6.6277065 | AI12: 0.00086000003 | AJ12: 418935472128 | AK12: 1.725 | AL12: 2.13 | AM12: 17.044315 | AN12: 465759600640
A13: 13 | B13: Walmart Inc. | C13: Discount Stores | D13: 0.0639 | E13: 0.02387 | F13: 0.25099 | G13: 24181000192 | H13: 0.005 | I13: 0.045289997 | J13: 36600000512 | K13: 143754000000 | L13: 13358499840 | M13: 143.45 | O13: 0.928 | P13: 0.0652 | Q13: 62.382 | R13: 0.15539 | S13: 14759999488 | T13: 57322999808 | U13: 572753969152 | V13: 5.33 | W13: USD | X13: 205.141 | Y13: 0.264 | Z13: EQUITY | AA13: WMT | AB13: 0.743 | AC13: 11.625 | AD13: 6.72 | AE13: 2773880064 | AF13: 29.616 | AG13: 2.84 | AH13: 4.8436656 | AI13: 0.47501 | AJ13: 425459023872 | AL13: 2.73 | AM13: 21.346725 | AN13: 397913096192
A14: 14 | B14: Procter & Gamble Company (The) | C14: Household & Personal Products | D14: 0.27021998 | E14: 0.1852 | F14: 0.49445 | G14: 17972000768 | H14: 0.061 | I14: 0.23464 | J14: 21170999296 | K14: 39144000000 | L14: 11721624576 | M14: 152.83 | N14: 0.126 | O14: 0.672 | P14: 0.09514 | Q14: 79.418 | R14: 0.31092 | S14: 11544000512 | T14: 35653001216 | U14: 78346002432 | V14: 4.816 | W14: USD | X14: 32.166 | Y14: 0.441 | Z14: EQUITY | AA14: PG | AB14: 4.965 | AC14: 18.375 | AD14: 6.36 | AE14: 2419950080 | AF14: 18.7 | AG14: 5.472 | AH14: 8.172727 | AI14: 0.0011100001 | AJ14: 389018681344 | AK14: 0.096 | AL14: 3.98 | AM14: 24.029875 | AN14: 369840979968
A15: 15 | B15: Exxon Mobil Corporation | C15: Oil & Gas Integrated | D15: 0.16555999 | E15: 0.08259 | F15: 0.32276002 | G15: 48128999424 | H15: 0.794 | I15: 0.09599 | J15: 46186999808 | K15: 90045000000 | L15: 28528625664 | M15: 85.2 | O15: 1.044 | P15: 0.049840003 | Q15: 30.184 | R15: 0.13889 | S15: 6801999872 | T15: 53028999168 | U15: 278980984832 | V15: 1.607 | W15: USD | X15: 65.259 | Y15: 0.692 | Z15: EQUITY | AA15: XOM | AB15: 1.341 | AC15: 8.103 | AD15: 5.88 | AE15: 4233540096 | AF15: 37.932 | AG15: -1.386 | AH15: 2.2461245 | AI15: 0.00102 | AJ15: 374239297536 | AL15: 13.11 | AM15: 14.489795 | AN15: 363009933312
A16: 17 | B16: Mastercard Incorporated | C16: Credit Services | D16: 0.58217996 | E16: 0.46001998 | F16: 1 | G16: 9463000064 | H16: 0.266 | I16: 0.54374003 | J16: 10993999872 | K16: 18884000000 | L16: 8458124800 | M16: 349.02 | N16: 0.355 | O16: 1.288 | P16: 0.18013 | Q16: 197.963 | R16: 1.2473301 | S16: 7894000128 | T16: 14673000448 | U16: 18883999744 | V16: 8.076 | W16: USD | X16: 19.113 | Y16: 0.928 | Z16: EQUITY | AA16: MA | AB16: 19.041 | AC16: 32.706 | AD16: 10.53 | AE16: 974708992 | AF16: 6.814 | AG16: 8.13 | AH16: 51.221012 | AI16: 0.10855 | AJ16: 359572045824 | AK16: 0.333 | AL16: 1.73 | AM16: 33.145298 | AN16: 342932029440
A17: 18 | B17: Home Depot, Inc. (The) | C17: Home Improvement Retail | D17: 0.17396 | E17: 0.10791001 | F17: 0.33718 | G17: 14810000384 | H17: 0.098 | I17: 0.15505 | J17: 25693999104 | K17: 44853000000 | L17: 9990124544 | M17: 310.68 | N17: 0.233 | O17: 1.132 | P17: 0.20454 | Q17: 4373.43 | R17: 12.403111 | S17: 5066999808 | T17: 45264998400 | U17: 147699007488 | V17: 4.852 | W17: USD | X17: 138.978 | Y17: 0.32 | Z17: EQUITY | AA17: HD | AB17: 3.191 | AC17: 18.343 | AD17: 16.19 | AE17: 1044240000 | AF17: 0.989 | AG17: 14.955 | AH17: 314.13547 | AI17: 0.00061 | AJ17: 471301718016 | AK17: 0.203 | AL17: 1.95 | AM17: 19.189623 | AN17: 324424466432
A18: 19 | B18: Chevron Corporation | C18: Oil & Gas Integrated | D18: 0.21459 | E18: 0.10041001 | F18: 0.42565 | G18: 29199998976 | H18: 0.846 | I18: 0.09956 | J18: 33392001024 | K18: 66234000000 | M18: 169.31 | Q18: 27.316 | R18: 0.11645 | S18: 6032000000 | T18: 37347000320 | U18: 155606007808 | V18: 3.129 | W18: USD | X18: 81.214 | Z18: EQUITY | AA18: CVX | AB18: 1.877 | AC18: 8.748 | AD18: 9.51 | AE18: 1927689984 | AF18: 70.479 | AG18: 5.173 | AH18: 2.402276 | AI18: 0.00037 | AJ18: 292123443200 | AL18: -2.98 | AM18: 17.803364 | AN18: 326377177088
A19: 20 | B19: Pfizer, Inc. | C19: Drug Manufacturers—General | D19: 0.39382 | E19: 0.28684 | F19: 0.65414 | G19: 32291000320 | H19: 1.344 | I19: 0.32139 | J19: 27306000384 | K19: 33334000000 | L19: 42431250432 | M19: 52.78 | N19: 4.468 | O19: 1.385 | P19: 0.07777 | Q19: 52.496 | R19: 0.27747 | S19: 29702000640 | T19: 39879000064 | U19: 69336997888 | V19: 5.292 | W19: USD | X19: 12.407 | Y19: 1.088 | Z19: EQUITY | AA19: PFE | AB19: 4.565 | AC19: 11.592 | AD19: 49.43 | AE19: 5612870144 | AF19: 13.49 | AG19: 3.501 | AH19: 3.9125278 | AI19: 0.00037999998 | AJ19: 316521611264 | AK19: 4.545 | AL19: 0.01 | AM19: 1.0677726 | AN19: 296247263232
A20: 21 | B20: AbbVie Inc. | C20: Drug Manufacturers—General | D20: 0.50286996 | E20: 0.20538001 | F20: 0.69338 | H20: 0.074 | I20: 0.34765 | J20: 28259663872 | K20: 38966000000 | M20: 161.33 | N20: 248.779 | Q20: 594.66 | R20: 0.86594003 | S20: 12248999936 | T20: 80737001472 | U20: 56197001216 | V20: 6.929 | W20: USD | X20: 31.625 | Z20: EQUITY | AA20: ABBV | AB20: 5.808 | AC20: 11.55 | AD20: 13.97 | AE20: 1767879936 | AF20: 7.665 | AG20: 4.196 | AH20: 21.047619 | AI20: 0.00107 | AJ20: 326395723776 | AK20: 111.333 | AL20: 2.38 | AM20: 11.548318 | AN20: 285212082176
A21: 22 | B21: Eli Lilly and Company | C21: Drug Manufacturers—General | D21: 0.34789002 | E21: 0.21515 | F21: 0.76413 | G21: 6919399936 | H21: 0.18 | I21: 0.29496 | J21: 9656999936 | K21: 19056500000 | L21: 3820699904 | M21: 289.02 | N21: -0.083 | O21: 1.302 | P21: 0.11108 | Q21: 215.45 | R21: 0.92237 | S21: 3852499968 | T21: 17137099776 | U21: 27758499840 | V21: 4.249 | W21: USD | X21: 30.578 | Y21: 0.793 | Z21: EQUITY | AA21: LLY | AB21: 8.955 | AC21: 25.742 | AD21: 7.49 | AE21: 956592000 | AF21: 8.552 | AG21: 6.55 | AH21: 33.7956 | AI21: 0.0015199999 | AJ21: 248588304384 | AK21: -0.081 | AL21: 5.2 | AM21: 38.58745 | AN21: 276474200064
A22: 23 | B22: Coca-Cola Company (The) | C22: Beverages—Non-Alcoholic | D22: 0.35199 | E22: 0.23313999 | F22: 0.60723996 | G22: 12855000064 | H22: 0.161 | I22: 0.31123 | J22: 13306000384 | K22: 19581000000 | L22: 7007374848 | M22: 61.53 | N22: 0.425 | O22: 1.516 | P22: 0.07831 | Q22: 172.826 | R22: 0.39722002 | S22: 14871000064 | T22: 41707999232 | U22: 37802000384 | V22: 3.443 | W22: USD | X22: 8.771 | Y22: 1.173 | Z22: EQUITY | AA22: KO | AB22: 7.651 | AC22: 21.735 | AD22: 2.43 | AE22: 4319419904 | AF22: 5.135 | AG22: 2.031 | AH22: 11.982472 | AI22: 0.00636 | AJ22: 289208860672 | AK22: 0.423 | AL22: 2.72 | AM22: 25.320986 | AN22: 265773907968
A23: 24 | B23: Broadcom Inc. | C23: Semiconductors | D23: 0.53639 | E23: 0.24539 | F23: 0.73908997 | G23: 13763999744 | H23: 0.145 | I23: 0.31632 | J23: 14723999744 | K23: 20288000000 | L23: 11868749824 | M23: 628.87 | N23: 0.521 | O23: 2.641 | P23: 0.07164 | Q23: 161.163 | R23: 0.27556 | S23: 12163000320 | T23: 40272998400 | U23: 27449999360 | V23: 29.459 | W23: USD | X23: 66.951 | Y23: 2.266 | Z23: EQUITY | AA23: AVGO | AB23: 9.65 | AC23: 17.99 | AD23: 36.05 | AE23: 412873984 | AF23: 60.441 | AG23: 15 | AH23: 10.404692 | AI23: 0.02391 | AJ23: 264887189504 | AK23: 0.502 | AL23: 1.38 | AM23: 17.444384 | AN23: 259644063744
A24: 25 | B24: Walt Disney Company (The) | C24: Entertainment | D24: 0.12761 | E24: 0.029590001 | F24: 0.33058 | G24: 5567000064 | H24: 0.26 | I24: 0.051799998 | J24: 8602999808 | K24: 22287000000 | L24: 7388250112 | M24: 139.14 | O24: 1.083 | P24: 0.01077 | Q24: 57.044 | R24: 0.025390001 | S24: 15959000064 | T24: 58312998912 | U24: 67418001408 | V24: 8.78 | W24: USD | X24: 37.124 | Y24: 0.944 | Z24: EQUITY | AA24: DIS | AB24: 5.03 | AC24: 39.415 | AD24: 5.06 | AE24: 1817660032 | AF24: 48.709 | AG24: 1.094 | AH24: 2.8565562 | AI24: 0.00099 | AJ24: 339088572416 | AL24: 1.07 | AM24: 27.498024 | AN24: 252909207552
A25: 26 | B25: Costco Wholesale Corporation | C25: Discount Stores | D25: 0.046350002 | E25: 0.02543 | F25: 0.12755999 | G25: 9569000448 | H25: 0.166 | I25: 0.03744 | J25: 9413000192 | K25: 25245000000 | L25: 687625024 | M25: 555.71 | N25: 0.137 | O25: 1.015 | P25: 0.07643 | Q25: 53.237 | R25: 0.30563 | S25: 13475999744 | T25: 10115000320 | U25: 203084005376 | V25: 30.39 | W25: USD | X25: 458.227 | Y25: 0.462 | Z25: EQUITY | AA25: COST | AB25: 1.105 | AC25: 23.838 | AD25: 13.96 | AE25: 443432000 | AF25: 41.636 | AG25: 11.63 | AH25: 13.346864 | AI25: 0.00204 | AJ25: 224390807552 | AK25: 0.136 | AL25: 4.42 | AM25: 39.80731 | AN25: 246419603456
A26: 27 | B26: Pepsico, Inc. | C26: Beverages—Non-Alcoholic | D26: 0.18109 | E26: 0.10617 | F26: 0.53927 | G26: 11123999744 | H26: 0.116 | I26: 0.15435 | J26: 13886000128 | K26: 38637000000 | L26: 4287749888 | M26: 165.24 | N26: -0.03 | O26: 0.945 | P26: 0.079840004 | Q26: 258.017 | R26: 0.55412996 | S26: 6849999872 | T26: 41257000960 | U26: 76681003008 | V26: 4.954 | W26: USD | X26: 55.546 | Y26: 0.654 | Z26: EQUITY | AA26: PEP | AB26: 3.574 | AC26: 19.735 | AD26: 6.74 | AE26: 1382649984 | AF26: 11.484 | AG26: 5.87 | AH26: 14.388715 | AI26: 0.00135 | AJ26: 274041962496 | AK26: -0.029 | AL26: 2.85 | AM26: 24.516321 | AN26: 228469096448
A27: 28 | B27: Cisco Systems, Inc. | C27: Communication Equipment | D27: 0.31235 | E27: 0.2244 | F27: 0.63726 | G27: 14785000448 | H27: 0.081 | I27: 0.27665 | J27: 15864000512 | K27: 31894000000 | L27: 10929999872 | M27: 54.97 | N27: 0.373 | O27: 1.618 | P27: 0.09196 | Q27: 25.032 | R27: 0.28190002 | S27: 23352000512 | T27: 10689000448 | U27: 50788999168 | V27: 5.537 | W27: USD | X27: 12.038 | Y27: 1.408 | Z27: EQUITY | AA27: CSCO | AB27: 4.227 | AC27: 13.532 | AD27: 3.68 | AE27: 4217609984 | AF27: 10.126 | AG27: 2.69 | AH27: 5.4285994 | AI27: 0.0007 | AJ27: 214665986048 | AK27: 0.371 | AL27: 2.73 | AM27: 14.9375 | AN27: 231842021376
A28: 29 | B28: Thermo Fisher Scientific Inc | C28: Diagnostics & Research | D28: 0.32687 | E28: 0.19701 | F28: 0.51603 | G28: 9543000064 | H28: 0.014 | I28: 0.26077 | J28: 12817000448 | K28: 20234000000 | L28: 5478624768 | M28: 574.29 | N28: -0.331 | O28: 1.504 | P28: 0.07801 | Q28: 85.097 | R28: 0.20476 | S28: 4477000192 | T28: 34870001664 | U28: 39210999808 | V28: 11.363 | W28: USD | X28: 99.52 | Y28: 0.933 | Z28: EQUITY | AA28: TMO | AB28: 6.206 | AC28: 18.986 | AD28: 21.73 | AE28: 394048000 | AF28: 98.237 | AG28: 21.544 | AH28: 5.845964 | AI28: 0.00207 | AJ28: 243341983744 | AK28: -0.336 | AL28: 2.23 | AM28: 26.42844 | AN28: 226297823232
A29: 30 | B29: Oracle Corporation | C29: Software—Infrastructure | D29: 0.44465 | E29: 0.24788 | F29: 0.79958 | G29: 10254999552 | H29: 0.057 | I29: 0.38564 | J29: 18407999488 | K29: 32624000000 | L29: 9675875328 | M29: 81.73 | O29: 1.646 | P29: 0.092 | S29: 22837999616 | T29: 78431002624 | U29: 41399001088 | V29: 8.552 | W29: USD | X29: 14.754 | Y29: 1.446 | Z29: EQUITY | AA29: ORCL | AB29: 6.288 | AC29: 14.141 | AD29: 5.26 | AE29: 2670449920 | AF29: -3.782 | AG29: 3.543 | AI29: 0.41914 | AJ29: 260298489856 | AL29: 1.91 | AM29: 15.538023 | AN29: 218255884288
A30: 31 | B30: Accenture plc | C30: Information Technology Services | D30: 0.16804 | E30: 0.11533 | F30: 0.32348 | G30: 7903174144 | H30: 0.272 | I30: 0.15195 | J30: 9030121472 | K30: 16364128000 | L30: 6319962112 | M30: 327.71 | N30: 0.197 | O30: 1.223 | P30: 0.12456001 | Q30: 16.607 | R30: 0.31948 | S30: 5644085248 | T30: 3477277952 | U30: 53736357888 | V30: 8.931 | W30: USD | X30: 84.725 | Y30: 1.101 | Z30: EQUITY | AA30: ACN | AB30: 4.198 | AC30: 24.983 | AD30: 10.45 | AE30: 632001024 | AF30: 32.2 | AG30: 9.613 | AH30: 10.177329 | AI30: 0.00123 | AJ30: 225603960832 | AK30: 0.194 | AL30: 3.82 | AM30: 31.359808 | AN30: 207279521792
A31: 32 | B31: Verizon Communications Inc. | C31: Telecom Services | D31: 0.37467 | E31: 0.16419001 | F31: 0.58188 | G31: 40457998336 | H31: 0.043 | I31: 0.25285998 | J31: 50295001088 | K31: 77091000000 | L31: -24466874368 | M31: 51.28 | N31: 0.473 | O31: 0.974 | P31: 0.06523 | Q31: 228.038 | R31: 0.31167 | S31: 10152999936 | T31: 178984992768 | U31: 134238003200 | V31: 2.452 | W31: USD | X31: 32.413 | Y31: 0.799 | Z31: EQUITY | AA31: VZ | AB31: 2.918 | AC31: 7.787 | AD31: 5.4 | AE31: 4197760000 | AF31: 18.609 | AG31: 5.32 | AH31: 2.755656 | AI31: 0.00016000001 | AJ31: 391651557376 | AK31: 0.471 | AL31: 2.62 | AM31: 9.496296 | AN31: 215261134848
A32: 33 | B32: Salesforce.com Inc | C32: Software—Application | D32: 0.13629 | E32: 0.06961 | F32: 0.74017996 | G32: 6192000000 | H32: 0.266 | I32: 0.03887 | J32: 3404999936 | K32: 15814000000 | L32: 8601624576 | M32: 211.03 | N32: -0.591 | O32: 1.061 | P32: 0.00828 | Q32: 25.131 | R32: 0.035720002 | S32: 9390999552 | T32: 14337999872 | U32: 24982999040 | V32: 9.534 | W32: USD | X32: 26.634 | Y32: 0.892 | Z32: EQUITY | AA32: CRM | AB32: 8.395 | AC32: 61.594 | AD32: 4.71 | AE32: 985000000 | AF32: 57.982 | AG32: 1.818 | AH32: 3.6395779 | AI32: 0.03408 | AJ32: 209728503808 | AK32: -0.567 | AL32: 5.29 | AM32: 44.80467 | AN32: 207864545280
A33: 34 | B33: Comcast Corporation | C33: Entertainment | D33: 0.2935 | E33: 0.12731 | F33: 0.66587996 | G33: 26499000320 | H33: 0.187 | I33: 0.17506 | J33: 33387999232 | K33: 70443000000 | L33: 10249124864 | M33: 47.13 | N33: 0.955 | O33: 1.026 | P33: 0.04559 | Q33: 104.661 | R33: 0.15312 | S33: 11806000128 | T33: 102385999872 | U33: 113757003776 | V33: 2.584 | W33: USD | X33: 24.781 | Y33: 0.889 | Z33: EQUITY | AA33: CMCSA | AB33: 2.868 | AC33: 9.772 | AD33: 3.69 | AE33: 4559479808 | AF33: 20.964 | AG33: 3.109 | AH33: 2.2481396 | AI33: 0.00676 | AJ33: 326278709248 | AK33: 0.999 | AL33: 0.87 | AM33: 12.772358 | AN33: 215333208064
A34: 35 | B34: Intel Corporation | C34: Semiconductors | D34: 0.42865002 | E34: 0.25142 | F34: 0.55445 | G34: 29991000064 | H34: 0.028 | I34: 0.27943 | J34: 33873999872 | K34: 43815000000 | L34: 1480125056 | M34: 51.83 | N34: -0.209 | O34: 2.102 | P34: 0.08586001 | Q34: 40.508 | R34: 0.22522 | S34: 28412999680 | T34: 38641000448 | U34: 79023996928 | V34: 6.978 | W34: USD | X34: 19.469 | Y34: 1.38 | Z34: EQUITY | AA34: INTC | AB34: 2.584 | AC34: 6.028 | AD34: 3.7 | AE34: 4067000064 | AF34: 22.151 | AG34: 5.158 | AH34: 2.3398495 | AI34: 0.0007 | AJ34: 204177358848 | AK34: -0.211 | AL34: 3.18 | AM34: 14.008108 | AN34: 210792628224
A35: 36 | B35: Abbott Laboratories | C35: Medical Devices | D35: 0.29229 | E35: 0.17122 | F35: 0.5685 | G35: 11264000000 | H35: 0.234 | I35: 0.20906 | J35: 12366000128 | K35: 19611000000 | L35: 8126875136 | M35: 118.95 | N35: 0.696 | O35: 1.826 | P35: 0.0774 | Q35: 53.112 | R35: 0.21862 | S35: 9692000256 | T35: 18396999680 | U35: 42308001792 | V35: 5.481 | W35: USD | X35: 23.815 | Y35: 1.251 | Z35: EQUITY | AA35: ABT | AB35: 5.885 | AC35: 20.136 | AD35: 4.76 | AE35: 1768290048 | AF35: 19.466 | AG35: 4.03 | AH35: 6.1106544 | AI35: 0.00728 | AJ35: 249001328640 | AK35: 0.705 | AL35: 2.03 | AM35: 24.989494 | AN35: 210338103296
A36: 37 | B36: Nike, Inc. | C36: Footwear & Accessories | D36: 0.17238002 | E36: 0.13322 | F36: 0.45981 | G36: 7169999872 | H36: 0.01 | I36: 0.15739 | J36: 7982000128 | K36: 20001000000 | L36: 4678624768 | M36: 133.7 | N36: 0.064 | O36: 3.068 | P36: 0.12352 | Q36: 85.252 | R36: 0.48263 | S36: 15102999552 | T36: 12723000320 | U36: 46306000896 | V36: 9.551 | W36: USD | X36: 29.3 | Y36: 2.128 | Z36: EQUITY | AA36: NKE | AB36: 4.736 | AC36: 27.473 | AD36: 4.82 | AE36: 1277810048 | AF36: 9.431 | AG36: 3.81 | AH36: 14.176652 | AI36: 0.012209999 | AJ36: 219285979136 | AK36: 0.069 | AL36: 2.89 | AM36: 27.738588 | AN36: 211623018496
A37: 38 | B37: Danaher Corporation | C37: Diagnostics & Research | D37: 0.35092998 | E37: 0.21841 | F37: 0.61304003 | G37: 8358000128 | H37: 0.205 | I37: 0.27732 | J37: 10336000000 | K37: 18056000000 | L37: 5476250112 | M37: 287.53 | N37: 0.444 | O37: 1.431 | P37: 0.06407 | Q37: 51.513 | R37: 0.14942001 | S37: 2585999872 | T37: 23271999488 | U37: 29453000704 | V37: 3.615 | W37: USD | X37: 41.216 | Y37: 0.887 | Z37: EQUITY | AA37: DHR | AB37: 7.202 | AC37: 20.522 | AD37: 10.14 | AE37: 714577024 | AF37: 56.239 | AG37: 7.882 | AH37: 5.112644 | AI37: 0.11138 | AJ37: 212116029440 | AK37: 0.441 | AL37: 1.46 | AM37: 28.356014 | AN37: 205462323200
A38: 39 | B38: Adobe Inc. | C38: Software—Infrastructure | D38: 0.41681 | E38: 0.30548 | F38: 0.88185 | H38: 0.2 | I38: 0.36756 | J38: 6579333120 | K38: 13920000000 | M38: 431.62 | N38: -0.445 | O38: 1.248 | P38: 0.14076 | Q38: 31.581 | R38: 0.34368 | S38: 5798000128 | T38: 4672999936 | U38: 15784999936 | V38: 12.181 | W38: USD | X38: 33.092 | Y38: 1.107 | Z38: EQUITY | AA38: ADBE | AB38: 15.908 | AC38: 38.165 | AD38: 16.25 | AE38: 475800000 | AF38: 31.086 | AG38: 10.02 | AH38: 13.884707 | AI38: 0.00312 | AJ38: 251102642176 | AK38: -0.452 | AL38: 2.62 | AM38: 26.56123 | AN38: 205364789248
A39: 40 | B39: Merck & Company, Inc. | C39: Drug Manufacturers—General | D39: 0.40027002 | E39: 0.13681 | F39: 0.72669 | G39: 13084000256 | H39: 0.204 | I39: 0.33821 | J39: 21056999424 | K39: 34572000000 | L39: 9870499840 | M39: 81.34 | N39: 0.548 | O39: 1.309 | P39: 0.12133 | Q39: 73.728 | R39: 0.26036 | S39: 10042000384 | T39: 26441000960 | U39: 52607000576 | V39: 3.976 | W39: USD | X39: 20.787 | Y39: 0.869 | Z39: EQUITY | AA39: MRK | AB39: 4.011 | AC39: 10.02 | AD39: 7.2 | AE39: 2525939968 | AF39: 14.174 | AG39: 2.834 | AH39: 5.738676 | AI39: 0.00072999997 | AJ39: 210990940160 | AK39: 0.553 | AL39: 0.87 | AM39: 11.297222 | AN39: 205459947520
A40: 42 | B40: United Parcel Service, Inc. | C40: Integrated Freight & Logistics | D40: 0.11517999 | E40: 0.06832 | F40: 0.19872 | G40: 12936999936 | H40: 0.092 | I40: 0.08434 | J40: 10874000384 | K40: 11490000000 | L40: 3207875072 | M40: 215.35 | N40: 0.183 | O40: 1.476 | P40: 0.07768 | Q40: 212.383 | R40: 0.73033994 | S40: 10560000000 | T40: 25607000064 | U40: 94411997184 | V40: 12.15 | W40: USD | X40: 108.147 | Y40: 1.381 | Z40: EQUITY | AA40: UPS | AB40: 2.16 | AC40: 18.753 | AD40: 12.1 | AE40: 729158016 | AF40: 13.856 | AG40: 7.355 | AH40: 15.542004 | AI40: 7e-05 | AJ40: 203918901248 | AK40: 0.19 | AL40: 1.07 | AM40: 17.79752 | AN40: 187169734656
...

Sheet Clean_Data
A1: Sr.NO | B1: Company | C1: Industry | D1: Profit Margin | E1: Revenue Growth | F1: Current Price | G1: Current Ratio | H1: ROA | I1: Debt-to-Equity | J1: ROE | K1: Stock ticker | L1: EV/Revenue | M1: EV/EBITDA | N1: Price-to-Book | O1: PEG Ratio | P1: Forward P/E | Q1: Market Cap
A2: 1 | B2: Apple Inc. | C2: Consumer Electronics | D2: 0.26579002 | E2: 0.112 | F2: 174.72 | G2: 1.038 | H2: 0.19875 | I2: 170.714 | J2: 1.45567 | K2: AAPL | L2: 7.692 | M2: 22.697 | N2: 39.69105 | O2: 1.9 | P2: 26.634148 | Q2: 2851325607936
A3: 2 | B3: Microsoft Corporation | C3: Software—Infrastructure | D3: 0.38498002 | E3: 0.201 | F3: 303.68 | G3: 2.247 | H3: 0.15248999 | I3: 50.217 | J3: 0.49051 | K3: MSFT | L3: 12.069 | M3: 24.57 | N3: 14.233889 | O3: 1.87 | P3: 28.249302 | Q3: 2276649336832
A4: 3 | B4: Alphabet Inc. | C4: Internet Content & Information | D4: 0.29512 | E4: 0.324 | F4: 2830.43 | G4: 2.928 | H4: 0.14493 | I4: 11.329 | J4: 0.32069 | K4: GOOG | L4: 6.83 | M4: 19.307 | N4: 7.4476376 | O4: 1.22 | P4: 20.802807 | Q4: 1872632217600
A5: 4 | B5: Alphabet Inc. | C5: Internet Content & Information | D5: 0.29512 | E5: 0.324 | F5: 2833.46 | G5: 2.928 | H5: 0.14493 | I5: 11.329 | J5: 0.32069 | K5: GOOGL | L5: 6.838 | M5: 19.329 | N5: 7.4556103 | O5: 1.22 | P5: 20.841927 | Q5: 1871194226688
A6: 5 | B6: Amazon.com, Inc. | C6: Internet Retail | D6: 0.07101 | E6: 0.094 | F6: 3295.47 | G6: 1.136 | H6: 0.041929998 | I6: 100.864 | J6: 0.28806 | K6: AMZN | L6: 3.662 | M6: 29.071 | N6: 12.133496 | O6: 1.93 | P6: 45.236378 | Q6: 1676880117760
A7: 7 | B7: Tesla, Inc. | C7: Auto Manufacturers | D7: 0.07403 | E7: 0.568 | F7: 1010.64 | G7: 1.385 | H7: 0.055370003 | I7: 35.65 | J7: 0.15641 | K7: TSLA | L7: 24.547 | M7: 158.249 | N7: 37.507515 | O7: 2.52 | P7: 115.36987 | Q7: 1014945284096
A8: 8 | B8: NVIDIA Corporation | C8: Semiconductors | D8: 0.33806 | E8: 0.503 | F8: 276.92 | G8: 7.145 | H8: 0.15934 | I8: 49.697 | J8: 0.41939998 | K8: NVDA | L8: 29.858 | M8: 74.268 | N8: 29.112701 | O8: 1.71 | P8: 53.151634 | Q8: 690084642816
A9: 9 | B9: Meta Platforms, Inc. | C9: Internet Content & Information | D9: 0.33383998 | E9: 0.199 | F9: 221.82 | G9: 3.154 | H9: 0.17965001 | I9: 11.574 | J9: 0.31102 | K9: FB | L9: 4.586 | M9: 9.884 | N9: 4.6456394 | O9: 1.13 | P9: 15.588195 | Q9: 617050013696
A10: 10 | B10: UnitedHealth Group Incorporated | C10: Healthcare Plans | D10: 0.05523 | E10: 0.111 | F10: 513.03 | G10: 0.72 | H10: 0.0679 | I10: 62.929 | J10: 0.21985 | K10: UNH | L10: 1.754 | M10: 20.243 | N10: 6.876617 | O10: 1.84 | P10: 23.696537 | Q10: 483197845504
A11: 11 | B11: Visa Inc. | C11: Credit Services | D11: 0.51592 | E11: 0.241 | F11: 218.43 | G11: 1.395 | H11: 0.13035 | I11: 57.8 | J11: 0.35584998 | K11: V | L11: 18.203 | M11: 26.149
A12: 13 | B12: Johnson & Johnson | C12: Drug Manufacturers—General | D12: 0.22264 | E12: 0.104 | F12: 176.92 | G12: 1.348 | H12: 0.08842 | I12: 46.946 | J12: 0.30412 | K12: JNJ | L12: 4.467 | M12: 12.836 | N12: 6.6277065 | O12: 2.13 | P12: 17.044315 | Q12: 465759600640
A13: 14 | B13: Walmart Inc. | C13: Discount Stores | D13: 0.02387 | E13: 0.005 | F13: 143.45 | G13: 0.928 | H13: 0.0652 | I13: 62.382 | J13: 0.15539 | K13: WMT | L13: 0.743 | M13: 11.625 | N13: 4.8436656 | O13: 2.73 | P13: 21.346725 | Q13: 397913096192
A14: 15 | B14: Procter & Gamble Company (The) | C14: Household & Personal Products | D14: 0.1852 | E14: 0.061 | F14: 152.83 | G14: 0.672 | H14: 0.09514 | I14: 79.418 | J14: 0.31092 | K14: PG | L14: 4.965 | M14: 18.375 | N14: 8.172727 | O14: 3.98 | P14: 24.029875 | Q14: 369840979968
A15: 17 | B15: Exxon Mobil Corporation | C15: Oil & Gas Integrated | D15: 0.08259 | E15: 0.794 | F15: 85.2 | G15: 1.044 | H15: 0.049840003 | I15: 30.184 | J15: 0.13889 | K15: XOM | L15: 1.341 | M15: 8.103 | N15: 2.2461245 | O15: 13.11 | P15: 14.489795 | Q15: 363009933312
A16: 18 | B16: Mastercard Incorporated | C16: Credit Services | D16: 0.46001998 | E16: 0.266 | F16: 349.02 | G16: 1.288 | H16: 0.18013 | I16: 197.963 | J16: 1.2473301 | K16: MA | L16: 19.041 | M16: 32.706 | N16: 51.221012 | O16: 1.73 | P16: 33.145298 | Q16: 342932029440
A17: 19 | B17: Home Depot, Inc. (The) | C17: Home Improvement Retail | D17: 0.10791001 | E17: 0.098 | F17: 310.68 | G17: 1.132 | H17: 0.20454 | I17: 4373.43 | J17: 12.403111 | K17: HD | L17: 3.191 | M17: 18.343 | N17: 314.13547 | O17: 1.95 | P17: 19.189623 | Q17: 324424466432
A18: 20 | B18: Chevron Corporation | C18: Oil & Gas Integrated | D18: 0.10041001 | E18: 0.846 | F18: 169.31 | I18: 27.316 | J18: 0.11645 | K18: CVX | L18: 1.877 | M18: 8.748 | N18: 2.402276 | O18: -2.98 | P18: 17.803364 | Q18: 326377177088
A19: 21 | B19: Pfizer, Inc. | C19: Drug Manufacturers—General | D19: 0.28684 | E19: 1.344 | F19: 52.78 | G19: 1.385 | H19: 0.07777 | I19: 52.496 | J19: 0.27747 | K19: PFE | L19: 4.565 | M19: 11.592 | N19: 3.9125278 | O19: 0.01 | P19: 1.0677726 | Q19: 296247263232
A20: 22 | B20: AbbVie Inc. | C20: Drug Manufacturers—General | D20: 0.20538001 | E20: 0.074 | F20: 161.33 | I20: 594.66 | J20: 0.86594003 | K20: ABBV | L20: 5.808 | M20: 11.55 | N20: 21.047619 | O20: 2.38 | P20: 11.548318 | Q20: 285212082176
A21: 23 | B21: Eli Lilly and Company | C21: Drug Manufacturers—General | D21: 0.21515 | E21: 0.18 | F21: 289.02 | G21: 1.302 | H21: 0.11108 | I21: 215.45 | J21: 0.92237 | K21: LLY | L21: 8.955 | M21: 25.742 | N21: 33.7956 | O21: 5.2 | P21: 38.58745 | Q21: 276474200064
A22: 24 | B22: Coca-Cola Company (The) | C22: Beverages—Non-Alcoholic | D22: 0.23313999 | E22: 0.161 | F22: 61.53 | G22: 1.516 | H22: 0.07831 | I22: 172.826 | J22: 0.39722002 | K22: KO | L22: 7.651 | M22: 21.735 | N22: 11.982472 | O22: 2.72 | P22: 25.320986 | Q22: 265773907968
A23: 25 | B23: Broadcom Inc. | C23: Semiconductors | D23: 0.24539 | E23: 0.145 | F23: 628.87 | G23: 2.641 | H23: 0.07164 | I23: 161.163 | J23: 0.27556 | K23: AVGO | L23: 9.65 | M23: 17.99 | N23: 10.404692 | O23: 1.38 | P23: 17.444384 | Q23: 259644063744
A24: 26 | B24: Walt Disney Company (The) | C24: Entertainment | D24: 0.029590001 | E24: 0.26 | F24: 139.14 | G24: 1.083 | H24: 0.01077 | I24: 57.044 | J24: 0.025390001 | K24: DIS | L24: 5.03 | M24: 39.415 | N24: 2.8565562 | O24: 1.07 | P24: 27.498024 | Q24: 252909207552
A25: 27 | B25: Costco Wholesale Corporation | C25: Discount Stores | D25: 0.02543 | E25: 0.166 | F25: 555.71 | G25: 1.015 | H25: 0.07643 | I25: 53.237 | J25: 0.30563 | K25: COST | L25: 1.105 | M25: 23.838 | N25: 13.346864 | O25: 4.42 | P25: 39.80731 | Q25: 246419603456
A26: 28 | B26: Pepsico, Inc. | C26: Beverages—Non-Alcoholic | D26: 0.10617 | E26: 0.116 | F26: 165.24 | G26: 0.945 | H26: 0.079840004 | I26: 258.017 | J26: 0.55412996 | K26: PEP | L26: 3.574 | M26: 19.735 | N26: 14.388715 | O26: 2.85 | P26: 24.516321 | Q26: 228469096448
A27: 29 | B27: Cisco Systems, Inc. | C27: Communication Equipment | D27: 0.2244 | E27: 0.081 | F27: 54.97 | G27: 1.618 | H27: 0.09196 | I27: 25.032 | J27: 0.28190002 | K27: CSCO | L27: 4.227 | M27: 13.532 | N27: 5.4285994 | O27: 2.73 | P27: 14.9375 | Q27: 231842021376
A28: 30 | B28: Thermo Fisher Scientific Inc | C28: Diagnostics & Research | D28: 0.19701 | E28: 0.014 | F28: 574.29 | G28: 1.504 | H28: 0.07801 | I28: 85.097 | J28: 0.20476 | K28: TMO | L28: 6.206 | M28: 18.986 | N28: 5.845964 | O28: 2.23 | P28: 26.42844 | Q28: 226297823232
A29: 31 | B29: Oracle Corporation | C29: Software—Infrastructure | D29: 0.24788 | E29: 0.057 | F29: 81.73 | G29: 1.646 | H29: 0.092 | I29: 0 | K29: ORCL | L29: 6.288 | M29: 14.141 | O29: 1.91 | P29: 15.538023 | Q29: 218255884288
A30: 32 | B30: Accenture plc | C30: Information Technology Services | D30: 0.11533 | E30: 0.272 | F30: 327.71 | G30: 1.223 | H30: 0.12456001 | I30: 16.607 | J30: 0.31948 | K30: ACN | L30: 4.198 | M30: 24.983 | N30: 10.177329 | O30: 3.82 | P30: 31.359808 | Q30: 207279521792
A31: 33 | B31: Verizon Communications Inc. | C31: Telecom Services | D31: 0.16419001 | E31: 0.043 | F31: 51.28 | G31: 0.974 | H31: 0.06523 | I31: 228.038 | J31: 0.31167 | K31: VZ | L31: 2.918 | M31: 7.787 | N31: 2.755656 | O31: 2.62 | P31: 9.496296 | Q31: 215261134848
A32: 34 | B32: Salesforce.com Inc | C32: Software—Application | D32: 0.06961 | E32: 0.266 | F32: 211.03 | G32: 1.061 | H32: 0.00828 | I32: 25.131 | J32: 0.035720002 | K32: CRM | L32: 8.395 | M32: 61.594 | N32: 3.6395779 | O32: 5.29 | P32: 44.80467 | Q32: 207864545280
A33: 35 | B33: Comcast Corporation | C33: Entertainment | D33: 0.12731 | E33: 0.187 | F33: 47.13 | G33: 1.026 | H33: 0.04559 | I33: 104.661 | J33: 0.15312 | K33: CMCSA | L33: 2.868 | M33: 9.772 | N33: 2.2481396 | O33: 0.87 | P33: 12.772358 | Q33: 215333208064
A34: 36 | B34: Intel Corporation | C34: Semiconductors | D34: 0.25142 | E34: 0.028 | F34: 51.83 | G34: 2.102 | H34: 0.08586001 | I34: 40.508 | J34: 0.22522 | K34: INTC | L34: 2.584 | M34: 6.028 | N34: 2.3398495 | O34: 3.18 | P34: 14.008108 | Q34: 210792628224
A35: 37 | B35: Abbott Laboratories | C35: Medical Devices | D35: 0.17122 | E35: 0.234 | F35: 118.95 | G35: 1.826 | H35: 0.0774 | I35: 53.112 | J35: 0.21862 | K35: ABT | L35: 5.885 | M35: 20.136 | N35: 6.1106544 | O35: 2.03 | P35: 24.989494 | Q35: 210338103296
A36: 38 | B36: Nike, Inc. | C36: Footwear & Accessories | D36: 0.13322 | E36: 0.01 | F36: 133.7 | G36: 3.068 | H36: 0.12352 | I36: 85.252 | J36: 0.48263 | K36: NKE | L36: 4.736 | M36: 27.473 | N36: 14.176652 | O36: 2.89 | P36: 27.738588 | Q36: 211623018496
A37: 39 | B37: Danaher Corporation | C37: Diagnostics & Research | D37: 0.21841 | E37: 0.205 | F37: 287.53 | G37: 1.431 | H37: 0.06407 | I37: 51.513 | J37: 0.14942001 | K37: DHR | L37: 7.202 | M37: 20.522 | N37: 5.112644 | O37: 1.46 | P37: 28.356014 | Q37: 205462323200
A38: 40 | B38: Adobe Inc. | C38: Software—Infrastructure | D38: 0.30548 | E38: 0.2 | F38: 431.62 | G38: 1.248 | H38: 0.14076 | I38: 31.581 | J38: 0.34368 | K38: ADBE | L38: 15.908 | M38: 38.165 | N38: 13.884707 | O38: 2.62 | P38: 26.56123 | Q38: 205364789248
A39: 42 | B39: Merck & Company, Inc. | C39: Drug Manufacturers—General | D39: 0.13681 | E39: 0.204 | F39: 81.34 | G39: 1.309 | H39: 0.12133 | I39: 73.728 | J39: 0.26036 | K39: MRK | L39: 4.011 | M39: 10.02 | N39: 5.738676 | O39: 0.87 | P39: 11.297222 | Q39: 205459947520
A40: 43 | B40: United Parcel Service, Inc. | C40: Integrated Freight & Logistics | D40: 0.06832 | E40: 0.092 | F40: 215.35 | G40: 1.476 | H40: 0.07768 | I40: 212.383 | J40: 0.73033994 | K40: UPS | L40: 2.16 | M40: 18.753 | N40: 15.542004 | O40: 1.07 | P40: 17.79752 | Q40: 187169734656
...

Sheet Industry_Benchmark
A1: Row Labels | B1: Average of Profit Margin | C1: Average of Revenue Growth | D1: Average of Current Ratio | E1: Average of ROA | F1: Average of Debt-to-Equity | G1: Average of ROE
A2: Aerospace & Defense | B2: 0.086845711 | C2: -0.0055714286 | D2: 1.9 | E2: 0.055819999 | F2: 56.095714 | G2: 0.332018
A3: Agricultural Inputs | B3: 0.10668001 | C3: 0.273 | D3: 1.812 | E3: 0.013890001 | F3: 9.9 | G3: 0.071609996
A4: Apparel Retail | B4: 0.05846 | C4: 0.239 | D4: 1.287 | E4: 0.07801 | F4: 198.942 | G4: 0.44426
A5: Asset Management | B5: 0.30562332 | C5: 0.156 | D5: 2.0716667 | E5: 0.081486663 | F5: 31.016667 | G5: 0.32167
A6: Auto Manufacturers | B6: 0.094826665 | C6: 0.17033333 | D6: 1.2296667 | E6: 0.036796667 | F6: 163.52167 | G6: 0.25986001
A7: Beverages—Non-Alcoholic | B7: 0.20897 | C7: 0.13633333 | D7: 2.3876667 | E7: 0.10935333 | F7: 143.72033 | G7: 0.41078666
A8: Beverages—Wineries & Distilleries | B8: -0.0061000003 | C8: -0.048 | D8: 1.502 | E8: 0.06876 | F8: 90.09 | G8: -0.0011100001
A9: Biotechnology | B9: 0.46816001 | C9: 10.661333 | D9: 3.179 | E9: 0.25766333 | F9: 9.7806667 | G9: 0.62818334
A10: Building Products & Equipment | B10: 0.08071999 | C10: 0.117 | D10: 1.721 | E10: 0.06261 | F10: 145.94 | G10: 0.24882999
A11: Chemicals | B11: 0.11325 | C11: 0.528 | D11: 1.594 | E11: 0.07396 | F11: 97.457 | G11: 0.39372003
A12: Communication Equipment | B12: 0.1895 | C12: 0.1045 | D12: 1.4995 | E12: 0.099320003 | F12: 12.516 | G12: 0.28190002
A13: Computer Hardware | B13: 0.19272 | C13: 0.165 | D13: 2.913 | E13: 0.103835 | F13: 0.797 | G13: 0.22579001
... A83: Grand Total | B83: 0.16991376 | C83: 0.35693805 | D83: 1.5702377 | E83: 0.079556592 | F83: 139.95073 | G83: 0.51881474

Sheet Company_Scoring
A1: Company | B1: Stock ticker | C1: Industry | D1: Profit Margin | E1: Industry Avg Profit Margin | F1: Profit Margin Difference | G1: Profit Score | H1: Revenue Growth | I1: Industry Avg Revenue Growth | J1: Revenue Growth Difference | K1: Growth Score | L1: Current Ratio | M1: Industry Avg Current Ratio | N1: Current Ratio Difference | O1: Liquidity Score | P1: ROA | Q1: Industry Avg ROA | R1: ROA Difference | S1: ROA Score | T1: Debt-to-Equity | U1: Industry Avg Debt-to-Equity | V1: Debt Difference | W1: Leverage Score | X1: ROE | Y1: Industry Avg ROE | Z1: ROE Difference | AA1: ROE Score | AB1: Financial Health Score | AC1: Financial Health % | AD1: Financial Health Rating
A2: Verizon Communications Inc. | B2: VZ | C2: Telecom Services | D2: 0.16419001 | E2: =_xlfn.XLOOKUP(C2,Industry_Benchmark!$A$2:$A$82,Industry_Benchmark!$B$2:$B$82,"") -> 0.06952667 | F2: =D2-E2 -> 0.09466334 | G2: =IF(F2>0,1,0) -> 1 | H2: 0.043 | I2: =_xlfn.XLOOKUP(C2,Industry_Benchmark!$A$2:$A$82,Industry_Benchmark!$C$2:$C$82,"") -> 0.0026666667 | J2: =H2-I2 -> 0.040333333 | K2: =IF(J2>0,1,0) -> 1 | L2: 0.974 | M2: =_xlfn.XLOOKUP(C2,Industry_Benchmark!$A$2:$A$82,Industry_Benchmark!$D$2:$D$82,"") -> 0.85466667 | N2: =L2-M2 -> 0.11933333 | O2: =IF(N2>0,1,0) -> 1 | P2: 0.06523 | Q2: =_xlfn.XLOOKUP(C2,Industry_Benchmark!$A$2:$A$82,Industry_Benchmark!$E$2:$E$82,"") -> 0.044393333 | R2: =P2-Q2 -> 0.020836667 | S2: =IF(R2>0,1,0) -> 1 | T2: 228.038 | U2: =_xlfn.XLOOKUP(C2,Industry_Benchmark!$A$2:$A$82,Industry_Benchmark!$F$2:$F$82,"") -> 167.02767 | V2: =T2-U2 -> 61.010333 | W2: =IF(V2>0,1,0) -> 1 | X2: 0.31167 | Y2: =_xlfn.XLOOKUP(C2,Industry_Benchmark!$A$2:$A$82,Industry_Benchmark!$G$2:$G$82,"") -> 0.12344333 | Z2: =X2-Y2 -> 0.18822667 | AA2: =IF(Z2>0,1,0) -> 1 | AB2: =SUM(G2,K2,O2,S2,W2,AA2) -> 6 | AC2: =AB2/6 -> 1 | AD2: {=_xlfn.IFS( AB2=6,"Excellent", AB2=5,"Strong", AB2=4,"Good", AB2=3,"Average", AB2<=2,"Weak" )} -> Excellent
A3: Illinois Tool Works Inc. | B3: ITW | C3: Specialty Industrial Machinery | D3: 0.19135 | E3: =_xlfn.XLOOKUP(C3,Industry_Benchmark!$A$2:$A$82,Industry_Benchmark!$B$2:$B$82,"") -> 0.12041 | F3: =D3-E3 -> 0.070939999 | G3: =IF(F3>0,1,0) -> 1 | H3: 0.075 | I3: =_xlfn.XLOOKUP(C3,Industry_Benchmark!$A$2:$A$82,Industry_Benchmark!$C$2:$C$82,"") -> 0.070857143 | J3: =H3-I3 -> 0.0041428571 | K3: =IF(J3>0,1,0) -> 1 | L3: 2.195 | M3: =_xlfn.XLOOKUP(C3,Industry_Benchmark!$A$2:$A$82,Industry_Benchmark!$D$2:$D$82,"") -> 1.469 | N3: =L3-M3 -> 0.726 | O3: =IF(N3>0,1,0) -> 1 | P3: 0.14562 | Q3: =_xlfn.XLOOKUP(C3,Industry_Benchmark!$A$2:$A$82,Industry_Benchmark!$E$2:$E$82,"") -> 0.066908572 | R3: =P3-Q3 -> 0.078711428 | S3: =IF(R3>0,1,0) -> 1 | T3: 216.175 | U3: =_xlfn.XLOOKUP(C3,Industry_Benchmark!$A$2:$A$82,Industry_Benchmark!$F$2:$F$82,"") -> 107.70214 | V3: =T3-U3 -> 108.47286 | W3: =IF(V3>0,1,0) -> 1 | X3: 0.8811 | Y3: =_xlfn.XLOOKUP(C3,Industry_Benchmark!$A$2:$A$82,Industry_Benchmark!$G$2:$G$82,"") -> 0.26455857 | Z3: =X3-Y3 -> 0.61654143 | AA3: =IF(Z3>0,1,0) -> 1 | AB3: =SUM(G3,K3,O3,S3,W3,AA3) -> 6 | AC3: =AB3/6 -> 1 | AD3: {=_xlfn.IFS( AB3=6,"Excellent", AB3=5,"Strong", AB3=4,"Good", AB3=3,"Average", AB3<=2,"Weak" )} -> Excellent
A4: Public Storage | B4: PSA | C4: REIT—Industrial | D4: 0.50629 | E4: =_xlfn.XLOOKUP(C4,Industry_Benchmark!$A$2:$A$82,Industry_Benchmark!$B$2:$B$82,"") -> 0.454235 | F4: =D4-E4 -> 0.052055 | G4: =IF(F4>0,1,0) -> 1 | H4: 0.228 | I4: =_xlfn.XLOOKUP(C4,Industry_Benchmark!$A$2:$A$82,Industry_Benchmark!$C$2:$C$82,"") -> 0.165 | J4: =H4-I4 -> 0.063 | K4: =IF(J4>0,1,0) -> 1 | L4: 2.075 | M4: =_xlfn.XLOOKUP(C4,Industry_Benchmark!$A$2:$A$82,Industry_Benchmark!$D$2:$D$82,"") -> 1.4615 | N4: =L4-M4 -> 0.6135 | O4: =IF(N4>0,1,0) -> 1 | P4: 0.0798 | Q4: =_xlfn.XLOOKUP(C4,Industry_Benchmark!$A$2:$A$82,Industry_Benchmark!$E$2:$E$82,"") -> 0.04979 | R4: =P4-Q4 -> 0.03001 | S4: =IF(R4>0,1,0) -> 1 | T4: 63.882 | U4: =_xlfn.XLOOKUP(C4,Industry_Benchmark!$A$2:$A$82,Industry_Benchmark!$F$2:$F$82,"") -> 55.8205 | V4: =T4-U4 -> 8.0615 | W4: =IF(V4>0,1,0) -> 1 | X4: 0.19327 | Y4: =_xlfn.XLOOKUP(C4,Industry_Benchmark!$A$2:$A$82,Industry_Benchmark!$G$2:$G$82,"") -> 0.126065 | Z4: =X4-Y4 -> 0.067205 | AA4: =IF(Z4>0,1,0) -> 1 | AB4: =SUM(G4,K4,O4,S4,W4,AA4) -> 6 | AC4: =AB4/6 -> 1 | AD4: {=_xlfn.IFS( AB4=6,"Excellent", AB4=5,"Strong", AB4=4,"Good", AB4=3,"Average", AB4<=2,"Weak" )} -> Excellent
A5: Microsoft Corporation | B5: MSFT | C5: Software—Infrastructure | D5: 0.38498002 | E5: =_xlfn.XLOOKUP(C5,Industry_Benchmark!$A$2:$A$82,Industry_Benchmark!$B$2:$B$82,"") -> 0.263494 | F5: =D5-E5 -> 0.12148602 | G5: =IF(F5>0,1,0) -> 1 | H5: 0.201 | I5: =_xlfn.XLOOKUP(C5,Industry_Benchmark!$A$2:$A$82,Industry_Benchmark!$C$2:$C$82,"") -> 0.2198 | J5: =H5-I5 -> -0.0188 | K5: =IF(J5>0,1,0) -> 0 | L5: 2.247 | M5: =_xlfn.XLOOKUP(C5,Industry_Benchmark!$A$2:$A$82,Industry_Benchmark!$D$2:$D$82,"") -> 1.6274 | N5: =L5-M5 -> 0.6196 | O5: =IF(N5>0,1,0) -> 1 | P5: 0.15248999 | Q5: =_xlfn.XLOOKUP(C5,Industry_Benchmark!$A$2:$A$82,Industry_Benchmark!$E$2:$E$82,"") -> 0.107218 | R5: =P5-Q5 -> 0.045271992 | S5: =IF(R5>0,1,0) -> 1 | T5: 50.217 | U5: =_xlfn.XLOOKUP(C5,Industry_Benchmark!$A$2:$A$82,Industry_Benchmark!$F$2:$F$82,"") -> 37.3778 | V5: =T5-U5 -> 12.8392 | W5: =IF(V5>0,1,0) -> 1 | X5: 0.49051 | Y5: =_xlfn.XLOOKUP(C5,Industry_Benchmark!$A$2:$A$82,Industry_Benchmark!$G$2:$G$82,"") -> 0.40269749 | Z5: =X5-Y5 -> 0.08781251 | AA5: =IF(Z5>0,1,0) -> 1 | AB5: =SUM(G5,K5,O5,S5,W5,AA5) -> 5 | AC5: =AB5/6 -> 0.83333333 | AD5: {=_xlfn.IFS( AB5=6,"Excellent", AB5=5,"Strong", AB5=4,"Good", AB5=3,"Average", AB5<=2,"Weak" )} -> Strong
A6: NVIDIA Corporation | B6: NVDA | C6: Semiconductors | D6: 0.33806 | E6: =_xlfn.XLOOKUP(C6,Industry_Benchmark!$A$2:$A$82,Industry_Benchmark!$B$2:$B$82,"") -> 0.246593 | F6: =D6-E6 -> 0.091467 | G6: =IF(F6>0,1,0) -> 1 | H6: 0.503 | I6: =_xlfn.XLOOKUP(C6,Industry_Benchmark!$A$2:$A$82,Industry_Benchmark!$C$2:$C$82,"") -> 0.3076 | J6: =H6-I6 -> 0.1954 | K6: =IF(J6>0,1,0) -> 1 | L6: 7.145 | M6: =_xlfn.XLOOKUP(C6,Industry_Benchmark!$A$2:$A$82,Industry_Benchmark!$D$2:$D$82,"") -> 2.9108 | N6: =L6-M6 -> 4.2342 | O6: =IF(N6>0,1,0) -> 1 | P6: 0.15934 | Q6: =_xlfn.XLOOKUP(C6,Industry_Benchmark!$A$2:$A$82,Industry_Benchmark!$E$2:$E$82,"") -> 0.121556 | R6: =P6-Q6 -> 0.037783998 | S6: =IF(R6>0,1,0) -> 1 | T6: 49.697 | U6: =_xlfn.XLOOKUP(C6,Industry_Benchmark!$A$2:$A$82,Industry_Benchmark!$F$2:$F$82,"") -> 77.0734 | V6: =T6-U6 -> -27.3764 | W6: =IF(V6>0,1,0) -> 0 | X6: 0.41939998 | Y6: =_xlfn.XLOOKUP(C6,Industry_Benchmark!$A$2:$A$82,Industry_Benchmark!$G$2:$G$82,"") -> 0.375412 | Z6: =X6-Y6 -> 0.043987982 | AA6: =IF(Z6>0,1,0) -> 1 | AB6: =SUM(G6,K6,O6,S6,W6,AA6) -> 5 | AC6: =AB6/6 -> 0.83333333 | AD6: {=_xlfn.IFS( AB6=6,"Excellent", AB6=5,"Strong", AB6=4,"Good", AB6=3,"Average", AB6<=2,"Weak" )} -> Strong
A7: Mastercard Incorporated | B7: MA | C7: Credit Services | D7: 0.46001998 | E7: =_xlfn.XLOOKUP(C7,Industry_Benchmark!$A$2:$A$82,Industry_Benchmark!$B$2:$B$82,"") -> 0.39226666 | F7: =D7-E7 -> 0.067753317 | G7: =IF(F7>0,1,0) -> 1 | H7: 0.266 | I7: =_xlfn.XLOOKUP(C7,Industry_Benchmark!$A$2:$A$82,Industry_Benchmark!$C$2:$C$82,"") -> 0.213 | J7: =H7-I7 -> 0.053 | K7: =IF(J7>0,1,0) -> 1 | L7: 1.288 | M7: =_xlfn.XLOOKUP(C7,Industry_Benchmark!$A$2:$A$82,Industry_Benchmark!$D$2:$D$82,"") -> 1.327 | N7: =L7-M7 -> -0.039 | O7: =IF(N7>0,1,0) -> 0 | P7: 0.18013 | Q7: =_xlfn.XLOOKUP(C7,Industry_Benchmark!$A$2:$A$82,Industry_Benchmark!$E$2:$E$82,"") -> 0.11619667 | R7: =P7-Q7 -> 0.063933332 | S7: =IF(R7>0,1,0) -> 1 | T7: 197.963 | U7: =_xlfn.XLOOKUP(C7,Industry_Benchmark!$A$2:$A$82,Industry_Benchmark!$F$2:$F$82,"") -> 99.888333 | V7: =T7-U7 -> 98.074667 | W7: =IF(V7>0,1,0) -> 1 | X7: 1.2473301 | Y7: =_xlfn.XLOOKUP(C7,Industry_Benchmark!$A$2:$A$82,Industry_Benchmark!$G$2:$G$82,"") -> 0.61539336 | Z7: =X7-Y7 -> 0.63193674 | AA7: =IF(Z7>0,1,0) -> 1 | AB7: =SUM(G7,K7,O7,S7,W7,AA7) -> 5 | AC7: =AB7/6 -> 0.83333333 | AD7: {=_xlfn.IFS( AB7=6,"Excellent", AB7=5,"Strong", AB7=4,"Good", AB7=3,"Average", AB7<=2,"Weak" )} -> Strong
A8: Home Depot, Inc. (The) | B8: HD | C8: Home Improvement Retail | D8: 0.10791001 | E8: =_xlfn.XLOOKUP(C8,Industry_Benchmark!$A$2:$A$82,Industry_Benchmark!$B$2:$B$82,"") -> 0.097080005 | F8: =D8-E8 -> 0.010830005 | G8: =IF(F8>0,1,0) -> 1 | H8: 0.098 | I8: =_xlfn.XLOOKUP(C8,Industry_Benchmark!$A$2:$A$82,Industry_Benchmark!$C$2:$C$82,"") -> 0.0625 | J8: =H8-I8 -> 0.0355 | K8: =IF(J8>0,1,0) -> 1 | L8: 1.132 | M8: =_xlfn.XLOOKUP(C8,Industry_Benchmark!$A$2:$A$82,Industry_Benchmark!$D$2:$D$82,"") -> 1.1625 | N8: =L8-M8 -> -0.0305 | O8: =IF(N8>0,1,0) -> 0 | P8: 0.20454 | Q8: =_xlfn.XLOOKUP(C8,Industry_Benchmark!$A$2:$A$82,Industry_Benchmark!$E$2:$E$82,"") -> 0.183375 | R8: =P8-Q8 -> 0.021165 | S8: =IF(R8>0,1,0) -> 1 | T8: 4373.43 | U8: =_xlfn.XLOOKUP(C8,Industry_Benchmark!$A$2:$A$82,Industry_Benchmark!$F$2:$F$82,"") -> 2186.715 | V8: =T8-U8 -> 2186.715 | W8: =IF(V8>0,1,0) -> 1 | X8: 12.403111 | Y8: =_xlfn.XLOOKUP(C8,Industry_Benchmark!$A$2:$A$82,Industry_Benchmark!$G$2:$G$82,"") -> 9.4907002 | Z8: =X8-Y8 -> 2.9124103 | AA8: =IF(Z8>0,1,0) -> 1 | AB8: =SUM(G8,K8,O8,S8,W8,AA8) -> 5 | AC8: =AB8/6 -> 0.83333333 | AD8: {=_xlfn.IFS( AB8=6,"Excellent", AB8=5,"Strong", AB8=4,"Good", AB8=3,"Average", AB8<=2,"Weak" )} -> Strong
A9: Accenture plc | B9: ACN | C9: Information Technology Services | D9: 0.11533 | E9: =_xlfn.XLOOKUP(C9,Industry_Benchmark!$A$2:$A$82,Industry_Benchmark!$B$2:$B$82,"") -> 0.08144 | F9: =D9-E9 -> 0.03389 | G9: =IF(F9>0,1,0) -> 1 | H9: 0.272 | I9: =_xlfn.XLOOKUP(C9,Industry_Benchmark!$A$2:$A$82,Industry_Benchmark!$C$2:$C$82,"") -> 0.1248 | J9: =H9-I9 -> 0.1472 | K9: =IF(J9>0,1,0) -> 1 | L9: 1.223 | M9: =_xlfn.XLOOKUP(C9,Industry_Benchmark!$A$2:$A$82,Industry_Benchmark!$D$2:$D$82,"") -> 1.1856 | N9: =L9-M9 -> 0.0374 | O9: =IF(N9>0,1,0) -> 1 | P9: 0.12456001 | Q9: =_xlfn.XLOOKUP(C9,Industry_Benchmark!$A$2:$A$82,Industry_Benchmark!$E$2:$E$82,"") -> 0.058694001 | R9: =P9-Q9 -> 0.065866005 | S9: =IF(R9>0,1,0) -> 1 | T9: 16.607 | U9: =_xlfn.XLOOKUP(C9,Industry_Benchmark!$A$2:$A$82,Industry_Benchmark!$F$2:$F$82,"") -> 80.5094 | V9: =T9-U9 -> -63.9024 | W9: =IF(V9>0,1,0) -> 0 | X9: 0.31948 | Y9: =_xlfn.XLOOKUP(C9,Industry_Benchmark!$A$2:$A$82,Industry_Benchmark!$G$2:$G$82,"") -> 0.15424 | Z9: =X9-Y9 -> 0.16524 | AA9: =IF(Z9>0,1,0) -> 1 | AB9: =SUM(G9,K9,O9,S9,W9,AA9) -> 5 | AC9: =AB9/6 -> 0.83333333 | AD9: {=_xlfn.IFS( AB9=6,"Excellent", AB9=5,"Strong", AB9=4,"Good", AB9=3,"Average", AB9<=2,"Weak" )} -> Strong
A10: Anthem, Inc. | B10: ANTM | C10: Healthcare Plans | D10: 0.041220002 | E10: =_xlfn.XLOOKUP(C10,Industry_Benchmark!$A$2:$A$82,Industry_Benchmark!$B$2:$B$82,"") -> 0.036041667 | F10: =D10-E10 -> 0.0051783347 | G10: =IF(F10>0,1,0) -> 1 | H10: 0.15 | I10: =_xlfn.XLOOKUP(C10,Industry_Benchmark!$A$2:$A$82,Industry_Benchmark!$C$2:$C$82,"") -> 0.11366667 | J10: =H10-I10 -> 0.036333333 | K10: =IF(J10>0,1,0) -> 1 | L10: 1.476 | M10: =_xlfn.XLOOKUP(C10,Industry_Benchmark!$A$2:$A$82,Industry_Benchmark!$D$2:$D$82,"") -> 1.11 | N10: =L10-M10 -> 0.366 | O10: =IF(N10>0,1,0) -> 1 | P10: 0.05371 | Q10: =_xlfn.XLOOKUP(C10,Industry_Benchmark!$A$2:$A$82,Industry_Benchmark!$E$2:$E$82,"") -> 0.046496666 | R10: =P10-Q10 -> 0.0072133338 | S10: =IF(R10>0,1,0) -> 1 | T10: 66.276 | U10: =_xlfn.XLOOKUP(C10,Industry_Benchmark!$A$2:$A$82,Industry_Benchmark!$F$2:$F$82,"") -> 78.132333 | V10: =T10-U10 -> -11.856333 | W10: =IF(V10>0,1,0) -> 0 | X10: 0.15835 | Y10: =_xlfn.XLOOKUP(C10,Industry_Benchmark!$A$2:$A$82,Industry_Benchmark!$G$2:$G$82,"") -> 0.14621 | Z10: =X10-Y10 -> 0.012139998 | AA10: =IF(Z10>0,1,0) -> 1 | AB10: =SUM(G10,K10,O10,S10,W10,AA10) -> 5 | AC10: =AB10/6 -> 0.83333333 | AD10: {=_xlfn.IFS( AB10=6,"Excellent", AB10=5,"Strong", AB10=4,"Good", AB10=3,"Average", AB10<=2,"Weak" )} -> Strong
A11: Lockheed Martin Corporation | B11: LMT | C11: Aerospace & Defense | D11: 0.094189994 | E11: =_xlfn.XLOOKUP(C11,Industry_Benchmark!$A$2:$A$82,Industry_Benchmark!$B$2:$B$82,"") -> 0.086845711 | F11: =D11-E11 -> 0.007344283 | G11: =IF(F11>0,1,0) -> 1 | H11: 0.041 | I11: =_xlfn.XLOOKUP(C11,Industry_Benchmark!$A$2:$A$82,Industry_Benchmark!$C$2:$C$82,"") -> -0.0055714286 | J11: =H11-I11 -> 0.046571429 | K11: =IF(J11>0,1,0) -> 1 | L11: 1.416 | M11: =_xlfn.XLOOKUP(C11,Industry_Benchmark!$A$2:$A$82,Industry_Benchmark!$D$2:$D$82,"") -> 1.9 | N11: =L11-M11 -> -0.484 | O11: =IF(N11>0,1,0) -> 0 | P11: 0.09624 | Q11: =_xlfn.XLOOKUP(C11,Industry_Benchmark!$A$2:$A$82,Industry_Benchmark!$E$2:$E$82,"") -> 0.055819999 | R11: =P11-Q11 -> 0.040420001 | S11: =IF(R11>0,1,0) -> 1 | T11: 119.555 | U11: =_xlfn.XLOOKUP(C11,Industry_Benchmark!$A$2:$A$82,Industry_Benchmark!$F$2:$F$82,"") -> 56.095714 | V11: =T11-U11 -> 63.459286 | W11: =IF(V11>0,1,0) -> 1 | X11: 0.74307 | Y11: =_xlfn.XLOOKUP(C11,Industry_Benchmark!$A$2:$A$82,Industry_Benchmark!$G$2:$G$82,"") -> 0.332018 | Z11: =X11-Y11 -> 0.411052 | AA11: =IF(Z11>0,1,0) -> 1 | AB11: =SUM(G11,K11,O11,S11,W11,AA11) -> 5 | AC11: =AB11/6 -> 0.83333333 | AD11: {=_xlfn.IFS( AB11=6,"Excellent", AB11=5,"Strong", AB11=4,"Good", AB11=3,"Average", AB11<=2,"Weak" )} -> Strong
A12: American Tower Corporation (REI | B12: AMT | C12: REIT—Specialty | D12: 0.27445 | E12: =_xlfn.XLOOKUP(C12,Industry_Benchmark!$A$2:$A$82,Industry_Benchmark!$B$2:$B$82,"") -> 0.1609075 | F12: =D12-E12 -> 0.1135425 | G12: =IF(F12>0,1,0) -> 1 | H12: 0.219 | I12: =_xlfn.XLOOKUP(C12,Industry_Benchmark!$A$2:$A$82,Industry_Benchmark!$C$2:$C$82,"") -> 0.1415 | J12: =H12-I12 -> 0.0775 | K12: =IF(J12>0,1,0) -> 1 | L12: 0.773 | M12: =_xlfn.XLOOKUP(C12,Industry_Benchmark!$A$2:$A$82,Industry_Benchmark!$D$2:$D$82,"") -> 0.9255 | N12: =L12-M12 -> -0.1525 | O12: =IF(N12>0,1,0) -> 0 | P12: 0.04348 | Q12: =_xlfn.XLOOKUP(C12,Industry_Benchmark!$A$2:$A$82,Industry_Benchmark!$E$2:$E$82,"") -> 0.03869 | R12: =P12-Q12 -> 0.00479 | S12: =IF(R12>0,1,0) -> 1 | T12: 434.983 | U12: =_xlfn.XLOOKUP(C12,Industry_Benchmark!$A$2:$A$82,Industry_Benchmark!$F$2:$F$82,"") -> 226.1405 | V12: =T12-U12 -> 208.8425 | W12: =IF(V12>0,1,0) -> 1 | X12: 0.34478 | Y12: =_xlfn.XLOOKUP(C12,Industry_Benchmark!$A$2:$A$82,Industry_Benchmark!$G$2:$G$82,"") -> 0.17199 | Z12: =X12-Y12 -> 0.17279 | AA12: =IF(Z12>0,1,0) -> 1 | AB12: =SUM(G12,K12,O12,S12,W12,AA12) -> 5 | AC12: =AB12/6 -> 0.83333333 | AD12: {=_xlfn.IFS( AB12=6,"Excellent", AB12=5,"Strong", AB12=4,"Good", AB12=3,"Average", AB12<=2,"Weak" )} -> Strong
A13: Intuitive Surgical, Inc. | B13: ISRG | C13: Medical Instruments & Supplies | D13: 0.29852 | E13: =_xlfn.XLOOKUP(C13,Industry_Benchmark!$A$2:$A$82,Industry_Benchmark!$B$2:$B$82,"") -> 0.1621425 | F13: =D13-E13 -> 0.1363775 | G13: =IF(F13>0,1,0) -> 1 | H13: 0.167 | I13: =_xlfn.XLOOKUP(C13,Industry_Benchmark!$A$2:$A$82,Industry_Benchmark!$C$2:$C$82,"") -> 0.13175 | J13: =H13-I13 -> 0.03525 | K13: =IF(J13>0,1,0) -> 1 | L13: 5.083 | M13: =_xlfn.XLOOKUP(C13,Industry_Benchmark!$A$2:$A$82,Industry_Benchmark!$D$2:$D$82,"") -> 2.83275 | N13: =L13-M13 -> 2.25025 | O13: =IF(N13>0,1,0) -> 1 | P13: 0.09207 | Q13: =_xlfn.XLOOKUP(C13,Industry_Benchmark!$A$2:$A$82,Industry_Benchmark!$E$2:$E$82,"") -> 0.08048 | R13: =P13-Q13 -> 0.01159 | S13: =IF(R13>0,1,0) -> 1 | T13: 0.728 | U13: =_xlfn.XLOOKUP(C13,Industry_Benchmark!$A$2:$A$82,Industry_Benchmark!$F$2:$F$82,"") -> 45.386 | V13: =T13-U13 -> -44.658 | W13: =IF(V13>0,1,0) -> 0 | X13: 0.15919 | Y13: =_xlfn.XLOOKUP(C13,Industry_Benchmark!$A$2:$A$82,Industry_Benchmark!$G$2:$G$82,"") -> 0.1407825 | Z13: =X13-Y13 -> 0.018407499 | AA13: =IF(Z13>0,1,0) -> 1 | AB13: =SUM(G13,K13,O13,S13,W13,AA13) -> 5 | AC13: =AB13/6 -> 0.83333333 | AD13: {=_xlfn.IFS( AB13=6,"Excellent", AB13=5,"Strong", AB13=4,"Good", AB13=3,"Average", AB13<=2,"Weak" )} -> Strong
... A39: Netflix, Inc. | B39: NFLX | C39: Entertainment | D39: 0.17639999 | E39: =_xlfn.XLOOKUP(C39,Industry_Benchmark!$A$2:$A$82,Industry_Benchmark!$B$2:$B$82,"") -> 0.104315 | F39: =D39-E39 -> 0.072084992 | G39: =IF(F39>0,1,0) -> 1 | H39: 0.163 | I39: =_xlfn.XLOOKUP(C39,Industry_Benchmark!$A$2:$A$82,Industry_Benchmark!$C$2:$C$82,"") -> 0.1755 | J39: =H39-I39 -> -0.0125 | K39: =IF(J39>0,1,0) -> 0 | L39: 1.17 | M39: =_xlfn.XLOOKUP(C39,Industry_Benchmark!$A$2:$A$82,Industry_Benchmark!$D$2:$D$82,"") -> 0.89125 | N39: =L39-M39 -> 0.27875 | O39: =IF(N39>0,1,0) -> 1 | P39: 0.10012 | Q39: =_xlfn.XLOOKUP(C39,Industry_Benchmark!$A$2:$A$82,Industry_Benchmark!$E$2:$E$82,"") -> 0.050625 | R39: =P39-Q39 -> 0.049495 | S39: =IF(R39>0,1,0) -> 1 | T39: 117.578 | U39: =_xlfn.XLOOKUP(C39,Industry_Benchmark!$A$2:$A$82,Industry_Benchmark!$F$2:$F$82,"") -> 174.17825 | V39: =T39-U39 -> -56.60025 | W39: =IF(V39>0,1,0) -> 0 | X39: 0.39387 | Y39: =_xlfn.XLOOKUP(C39,Industry_Benchmark!$A$2:$A$82,Industry_Benchmark!$G$2:$G$82,"") -> 0.18733 | Z39: =X39-Y39 -> 0.20654 | AA39: =IF(Z39>0,1,0) -> 1 | AB39: =SUM(G39,K39,O39,S39,W39,AA39) -> 4 | AC39: =AB39/6 -> 0.66666667 | AD39: {=_xlfn.IFS( AB39=6,"Excellent", AB39=5,"Strong", AB39=4,"Good", AB39=3,"Average", AB39<=2,"Weak" )} -> Good
A40: Philip Morris International Inc | B40: PM | C40: Tobacco | D40: 0.29247 | E40: =_xlfn.XLOOKUP(C40,Industry_Benchmark!$A$2:$A$82,Industry_Benchmark!$B$2:$B$82,"") -> 0.212055 | F40: =D40-E40 -> 0.080415 | G40: =IF(F40>0,1,0) -> 1 | H40: 0.091 | I40: =_xlfn.XLOOKUP(C40,Industry_Benchmark!$A$2:$A$82,Industry_Benchmark!$C$2:$C$82,"") -> 0.0325 | J40: =H40-I40 -> 0.0585 | K40: =IF(J40>0,1,0) -> 1 | L40: 0.998 | M40: =_xlfn.XLOOKUP(C40,Industry_Benchmark!$A$2:$A$82,Industry_Benchmark!$D$2:$D$82,"") -> 0.87 | N40: =L40-M40 -> 0.128 | O40: =IF(N40>0,1,0) -> 1 | P40: 0.2024 | Q40: =_xlfn.XLOOKUP(C40,Industry_Benchmark!$A$2:$A$82,Industry_Benchmark!$E$2:$E$82,"") -> 0.18736 | R40: =P40-Q40 -> 0.015039995 | S40: =IF(R40>0,1,0) -> 1 | T40: 0 | U40: =_xlfn.XLOOKUP(C40,Industry_Benchmark!$A$2:$A$82,Industry_Benchmark!$F$2:$F$82,"") -> 0 | V40: =T40-U40 -> 0 | W40: =IF(V40>0,1,0) -> 0 | Y40: =_xlfn.XLOOKUP(C40,Industry_Benchmark!$A$2:$A$82,Industry_Benchmark!$G$2:$G$82,"") -> 2.7119799 | Z40: =X40-Y40 -> -2.7119799 | AA40: =IF(Z40>0,1,0) -> 0 | AB40: =SUM(G40,K40,O40,S40,W40,AA40) -> 4 | AC40: =AB40/6 -> 0.66666667 | AD40: {=_xlfn.IFS( AB40=6,"Excellent", AB40=5,"Strong", AB40=4,"Good", AB40=3,"Average", AB40<=2,"Weak" )} -> Good
A41: ConocoPhillips | B41: COP | C41: Oil & Gas E&P | D41: 0.17315 | E41: =_xlfn.XLOOKUP(C41,Industry_Benchmark!$A$2:$A$82,Industry_Benchmark!$B$2:$B$82,"") -> 0.114568 | F41: =D41-E41 -> 0.058582 | G41: =IF(F41>0,1,0) -> 1 | H41: 1.771 | I41: =_xlfn.XLOOKUP(C41,Industry_Benchmark!$A$2:$A$82,Industry_Benchmark!$C$2:$C$82,"") -> 1.5186 | J41: =H41-I41 -> 0.2524 | K41: =IF(J41>0,1,0) -> 1 | L41: 1.335 | M41: =_xlfn.XLOOKUP(C41,Industry_Benchmark!$A$2:$A$82,Industry_Benchmark!$D$2:$D$82,"") -> 1.4502 | N41: =L41-M41 -> -0.1152 | O41: =IF(N41>0,1,0) -> 0 | P41: 0.10439 | Q41: =_xlfn.XLOOKUP(C41,Industry_Benchmark!$A$2:$A$82,Industry_Benchmark!$E$2:$E$82,"") -> 0.091554 | R41: =P41-Q41 -> 0.012836 | S41: =IF(R41>0,1,0) -> 1 | T41: 45.371 | U41: =_xlfn.XLOOKUP(C41,Industry_Benchmark!$A$2:$A$82,Industry_Benchmark!$F$2:$F$82,"") -> 71.0882 | V41: =T41-U41 -> -25.7172 | W41: =IF(V41>0,1,0) -> 0 | X41: 0.21471001 | Y41: =_xlfn.XLOOKUP(C41,Industry_Benchmark!$A$2:$A$82,Industry_Benchmark!$G$2:$G$82,"") -> 0.138068 | Z41: =X41-Y41 -> 0.076642008 | AA41: =IF(Z41>0,1,0) -> 1 | AB41: =SUM(G41,K41,O41,S41,W41,AA41) -> 4 | AC41: =AB41/6 -> 0.66666667 | AD41: {=_xlfn.IFS( AB41=6,"Excellent", AB41=5,"Strong", AB41=4,"Good", AB41=3,"Average", AB41<=2,"Weak" )} -> Good
A42: Amgen Inc. | B42: AMGN | C42: Drug Manufacturers—General | D42: 0.21767999 | E42: =_xlfn.XLOOKUP(C42,Industry_Benchmark!$A$2:$A$82,Industry_Benchmark!$B$2:$B$82,"") -> 0.21304125 | F42: =D42-E42 -> 0.00463874 | G42: =IF(F42>0,1,0) -> 1 | H42: 0.044 | I42: =_xlfn.XLOOKUP(C42,Industry_Benchmark!$A$2:$A$82,Industry_Benchmark!$C$2:$C$82,"") -> 0.270125 | J42: =H42-I42 -> -0.226125 | K42: =IF(J42>0,1,0) -> 0 | L42: 1.643 | M42: =_xlfn.XLOOKUP(C42,Industry_Benchmark!$A$2:$A$82,Industry_Benchmark!$D$2:$D$82,"") -> 1.4105714 | N42: =L42-M42 -> 0.23242857 | O42: =IF(N42>0,1,0) -> 1 | P42: 0.08696 | Q42: =_xlfn.XLOOKUP(C42,Industry_Benchmark!$A$2:$A$82,Industry_Benchmark!$E$2:$E$82,"") -> 0.095184286 | R42: =P42-Q42 -> -0.0082242857 | S42: =IF(R42>0,1,0) -> 0 | T42: 457.332 | U42: =_xlfn.XLOOKUP(C42,Industry_Benchmark!$A$2:$A$82,Industry_Benchmark!$F$2:$F$82,"") -> 212.024 | V42: =T42-U42 -> 245.308 | W42: =IF(V42>0,1,0) -> 1 | X42: 0.585 | Y42: =_xlfn.XLOOKUP(C42,Industry_Benchmark!$A$2:$A$82,Industry_Benchmark!$G$2:$G$82,"") -> 0.47294626 | Z42: =X42-Y42 -> 0.11205374 | AA42: =IF(Z42>0,1,0) -> 1 | AB42: =SUM(G42,K42,O42,S42,W42,AA42) -> 4 | AC42: =AB42/6 -> 0.66666667 | AD42: {=_xlfn.IFS( AB42=6,"Excellent", AB42=5,"Strong", AB42=4,"Good", AB42=3,"Average", AB42<=2,"Weak" )} -> Good
A43: Deere & Company | B43: DE | C43: Farm & Heavy Construction Machinery | D43: 0.13566 | E43: =_xlfn.XLOOKUP(C43,Industry_Benchmark!$A$2:$A$82,Industry_Benchmark!$B$2:$B$82,"") -> 0.131485 | F43: =D43-E43 -> 0.004175 | G43: =IF(F43>0,1,0) -> 1 | H43: 0.16 | I43: =_xlfn.XLOOKUP(C43,Industry_Benchmark!$A$2:$A$82,Industry_Benchmark!$C$2:$C$82,"") -> 0.194 | J43: =H43-I43 -> -0.034 | K43: =IF(J43>0,1,0) -> 0 | L43: 2.192 | M43: =_xlfn.XLOOKUP(C43,Industry_Benchmark!$A$2:$A$82,Industry_Benchmark!$D$2:$D$82,"") -> 1.824 | N43: =L43-M43 -> 0.368 | O43: =IF(N43>0,1,0) -> 1 | P43: 0.06355 | Q43: =_xlfn.XLOOKUP(C43,Industry_Benchmark!$A$2:$A$82,Industry_Benchmark!$E$2:$E$82,"") -> 0.058455 | R43: =P43-Q43 -> 0.005095 | S43: =IF(R43>0,1,0) -> 1 | T43: 264.864 | U43: =_xlfn.XLOOKUP(C43,Industry_Benchmark!$A$2:$A$82,Industry_Benchmark!$F$2:$F$82,"") -> 246.833 | V43: =T43-U43 -> 18.031 | W43: =IF(V43>0,1,0) -> 1 | X43: 0.3802 | Y43: =_xlfn.XLOOKUP(C43,Industry_Benchmark!$A$2:$A$82,Industry_Benchmark!$G$2:$G$82,"") -> 0.39367999 | Z43: =X43-Y43 -> -0.01347999 | AA43: =IF(Z43>0,1,0) -> 0 | AB43: =SUM(G43,K43,O43,S43,W43,AA43) -> 4 | AC43: =AB43/6 -> 0.66666667 | AD43: {=_xlfn.IFS( AB43=6,"Excellent", AB43=5,"Strong", AB43=4,"Good", AB43=3,"Average", AB43<=2,"Weak" )} -> Good
